Workbook

Sheet PAYABLES-2024
A2: PAYABLES-2026
A3: S# | B3: NAME | C3: AMOUNT
A4: 1 | B4: AL AZIZ LHR | C4: ='AL AZIZ-LHR-19'!G36 -> 64350
A5: 2 | B5: WAQAS FTC | C5: =39400+28700-18100-20000+27200+14100-26300-20000+4950+7750+32500-50000+60800-20000+5500-20000-26500+42600-22600+44350+17100-25000+16900-33350-20000+20750+18000+9250-28000-20000 -> 40000
A6: 4 | B6: KARACHI COMPUTERS 6TH ROAD | C6: =179795+15500+27380-50000-52600-20000-25000-52500+79545-75+58770-50000+29140-60000+386115-100000-36000-30000+49420-100000+1400+27570-50000-38460-40000+66265+20500-42000-40000+271800-250000+46945+123690-100000-47200-30000+81480+10000-96000-45480+247990-120000+36565-35550+12610-50000+46010-60000-57625-40000+293055+4300-100000-47000+69715-50000-30000-50000-40000-50000+5400+79420-30000+10300+72955-100000+70620-100000-42900-10000+53560+30350 -> 139775
A7: 5 | B7: ZAFAR & SONS RWP | C7: =' ZAFAR & SONS RWP 5 '!G36 -> 361700
A8: 6 | B8: FARHAN BAHI T.COM | C8: =30350+3000+100+100-15000+25000+40000+3380-33000+250000+100000+50000+53500-60000+2000+4500-7000-1000-5930-5000-2000-3000-5000-2000-3000-10000-2000-3000-5000-5000-5000-5000-5000-5000-5000-5000+80920-5000-3000-2920-5000-5000-3500+2000-3500-5000-5000-5000-10000-10000-2000-3000-5000-5000+3150+21950+96000+29700-2000-3800-5000-6500-3500-5000-5000-5000-5000-5000-5000-10000-10000-5000+120000+20000-13500-6500-5000-4000-6000-5000-4200-2000+5000+31250-2000-5000+25000-12000-10000+72000-101000-50000+35000-129000-50000+100000-100000-50000-107000+40000+60500+13000-100000+20000+22000+50000+4000+45000-103000+26500+9000+81000-46000+20000+30000+25000+50000+25000-150000+40000+100000+10000+100000-100000+10000+42900+13500-11000-360000+100000-13000-15000+114500+22000-9000+121000+13500-100000-20000-5000+22000+42900+25000+28000+26800-120000+6000-10000+154000+25000+6500-90000+50000+13750+86000+7000+45000+9200+12500-100000+11400+1500+25500+13000+20000+10000+125000+30000+40340+18500+4500 -> 906840
A9: 7 | B9: NAEEM BHAI PBM ISB LAPTOPS | C9: ='NAEEM BHI PBM ISB LAPTOPS 2'!G36 -> 355750
A10: 8 | B10: NASIM BAHI | C10: =+'NASNIM BHI-2'!G132 -> 590090
A11: 9 | B11: NAEEM BHAI PBM ISB | C11: ='NAEEM BHI PBM-3 '!G36 -> 111500
A12: 10 | B12: Abdul Rafay Accessories Supplier | C12: ='Abdul Rafay'!I105 -> 57825
A13: 11 | B13: ABDUL SATTAR BHAI UK | C13: =100000-80000 -> 20000
A14: 12 | B14: AHMED BAHI | C14: =94510-5000-10000-3000-500-3000-1000-3000-5200-5000-8800-2000-5000-5000-3000-5000-5000-3000-5500 -> 16510
A15: 13 | B15: LOAN FROM ABL TASNIM | C15: =324500+10000+15000+13500-15000+15000+34000-7500+120000+15000-15000-15000-12500-15000-15000-15000-12500+38000+15000-40000-21000-12500-15000-15000-7000-10000-12500-18300-7500-12759-29000-6500-5000-1000-2000-900 -> 261541
A16: 14 | B16: MUSA & ESSA | C16: =40000+120000+144000 -> 304000
A17: TOTAL | C17: =SUM(C4:C16) -> 3229881

Sheet NAEEM BHI PBM 1
A1: TASNIM COMPUTERS SALES & SERVICE
A2: NAEEM BHI PBM ISB LAPTOPS LEDGER
A3: FROM THE MONTH OF JANUARY 2024
A4: DATE | B4: TYPE | C4: REF# | D4: DESCRIPTION | E4: DEBIT | F4: CREDIT | G4: BALANCE
A6: 45008 | B6: PURCHASE | C6: BILL #0345 | D6: HP 840 G6 8GB/256GB | F6: 65000 | G6: =G5+F6-E6 -> 65000 | H6: =IF(G6=0,"NIL",IF(G6>0,"CR","DR")) -> CR
A7: 45008 | B7: PURCHASE | C7: BILL #0346 | D7: HP 450 G4 8GB/128/500GB | F7: 60000 | G7: =G6+F7-E7 -> 125000 | H7: =IF(G7=0,"NIL",IF(G7>0,"CR","DR")) -> CR
A8: 45008 | B8: PURCHASE | C8: BILL #0347 | D8: DELL 5580 TOUCH 1080 8GB/256 | F8: 65000 | G8: =G7+F8-E8 -> 190000 | H8: =IF(G8=0,"NIL",IF(G8>0,"CR","DR")) -> CR
A9: 45008 | B9: PURCHASE | C9: BILL #0348 | D9: DELL 5580 TOUCH 1080 8GB/256 | F9: 65000 | G9: =G8+F9-E9 -> 255000 | H9: =IF(G9=0,"NIL",IF(G9>0,"CR","DR")) -> CR
A10: 45374 | B10: PURCHASE | C10: BILL #0349 | D10: HP 840 G5 8GB/256GB | F10: 58000 | G10: =G9+F10-E10 -> 313000 | H10: =IF(G10=0,"NIL",IF(G10>0,"CR","DR")) -> CR
A11: 45374 | B11: PURCHASE | C11: BILL #0350 | D11: LENOVO T470 8GB/180 | F11: 49000 | G11: =G10+F11-E11 -> 362000 | H11: =IF(G11=0,"NIL",IF(G11>0,"CR","DR")) -> CR
A12: 45374 | B12: PURCHASE | C12: BILL #0351 | D12: DELL 7480 8GB/256GB | F12: 43000 | G12: =G11+F12-E12 -> 405000 | H12: =IF(G12=0,"NIL",IF(G12>0,"CR","DR")) -> CR
A13: 45374 | B13: PURCHASE | C13: BILL #0352 | D13: DELL 7480 8GB/256GB | F13: 43000 | G13: =G12+F13-E13 -> 448000 | H13: =IF(G13=0,"NIL",IF(G13>0,"CR","DR")) -> CR
A14: 45374 | B14: PURCHASE | C14: BILL #0353 | D14: DELL 7480 8GB/256GB | F14: 43000 | G14: =G13+F14-E14 -> 491000 | H14: =IF(G14=0,"NIL",IF(G14>0,"CR","DR")) -> CR
A15: 45374 | B15: PURCHASE | C15: BILL #0354 | D15: HP ELITEBOOK 840 G3 | F15: 45000 | G15: =G14+F15-E15 -> 536000 | H15: =IF(G15=0,"NIL",IF(G15>0,"CR","DR")) -> CR
A16: 45008 | B16: PURCHASE | C16: BILL #0355 | D16: DELL 3570 8GB/256GB | F16: 42000 | G16: =G15+F16-E16 -> 578000 | H16: =IF(G16=0,"NIL",IF(G16>0,"CR","DR")) -> CR
A17: 45374 | B17: PURCHASE | C17: BILL #0356 | D17: TOSHIBA PROTAG Z30 C 8GB/128GB | F17: 33500 | G17: =G16+F17-E17 -> 611500 | H17: =IF(G17=0,"NIL",IF(G17>0,"CR","DR")) -> CR
... A25: 45374 | B25: PURCHASE | C25: BILL #0364 | D25: DELL 6430 4GB/500GB | F25: 17000 | G25: =G24+F25-E25 -> 801000 | H25: =IF(G25=0,"NIL",IF(G25>0,"CR","DR")) -> CR
A26: 45375 | B26: PAYMENT | C26: 4624 | D26: ONLINE PAYMENT THROUGH BANK | E26: 45000 | G26: =G25+F26-E26 -> 756000 | H26: =IF(G26=0,"NIL",IF(G26>0,"CR","DR")) -> CR
A27: 45376 | B27: PURCHASE | C27: BILL #0364 | D27: LENOVO YOGA 460 360 TOUCH I5 6TH 8GB 256GB | F27: 48000 | G27: =G26+F27-E27 -> 804000 | H27: =IF(G27=0,"NIL",IF(G27>0,"CR","DR")) -> CR
A28: 45378 | B28: PURCHASE | C28: BILL #0364 | D28: HP ZBOOK I7 8TH GEN 16GB 256SSD | F28: 102000 | G28: =G27+F28-E28 -> 906000 | H28: =IF(G28=0,"NIL",IF(G28>0,"CR","DR")) -> CR
A29: 45383 | B29: RETURN | C29: BILL#0345 | D29: DELL LATITUDE 7480 I5 6TH 8/256 | E29: 43000 | G29: =G28+F29-E29 -> 863000 | H29: =IF(G29=0,"NIL",IF(G29>0,"CR","DR")) -> CR
A30: 45406 | B30: PAYMENT | C30: 6411 | D30: HP ZBOOK /DELL 6430 | E30: 122000 | G30: =G29+F30-E30 -> 741000 | H30: =IF(G30=0,"NIL",IF(G30>0,"CR","DR")) -> CR
A31: 45406 | B31: RETURN | C31: BILL #0364 | D31: DELL 7480 / LENOVO YOGA 360 | E31: 91000 | G31: =G30+F31-E31 -> 650000 | H31: =IF(G31=0,"NIL",IF(G31>0,"CR","DR")) -> CR
A32: 45414 | B32: PAYMENT | C32: 6411 | D32: HP ELITEBOOK 840 G5 I5 7TH GEN | E32: 58000 | G32: =G31+F32-E32 -> 592000 | H32: =IF(G32=0,"NIL",IF(G32>0,"CR","DR")) -> CR
A33: 45415 | B33: RETURN | C33: BILL #0364 | D33: DELL 5580 QTY 2 | E33: 130000 | G33: =G32+F33-E33 -> 462000 | H33: =IF(G33=0,"NIL",IF(G33>0,"CR","DR")) -> CR
A34: 45421 | B34: PAYMENT | C34: 6411 | D34: TOSHIBA Z30 I5 4TH GEN | E34: 27000 | G34: =G33+F34-E34 -> 435000 | H34: =IF(G34=0,"NIL",IF(G34>0,"CR","DR")) -> CR
A35: 45421 | B35: PURCHASE | C35: BILL#0345 | D35: DELL 5570 I7 6TH HQ 8GB/256GB SSD | F35: 60000 | G35: =G34+F35-E35 -> 495000 | H35: =IF(G35=0,"NIL",IF(G35>0,"CR","DR")) -> CR
D36: TOTAL BALANCE | E36: =SUM(E6:E35) -> 516000 | F36: =SUM(F6:F35) -> 1011000 | G36: =G5+F36-E36 -> 495000 | H36: =IF(G36=0,"NIL",IF(G36>0,"CR","DR")) -> CR

Sheet NAEEM BHI PBM-2
A1: TASNIM COMPUTERS SALES & SERVICE | J1: PAYABLE HOME
A2: NAEEM BHI PBM ISB LAPTOPS LEDGER
A3: FROM THE MONTH OF JANUARY 2024
A4: DATE | B4: TYPE | C4: REF# | D4: DESCRIPTION | E4: DEBIT | F4: CREDIT | G4: BALANCE
G5: ='NAEEM BHI PBM 1'!G36 -> 495000
A6: 45423 | B6: PURCHASE | C6: BILL#0345 | D6: LENOVO T450 I7 5TH 8GB 256GB +CHARGER | F6: 41000 | G6: =G5+F6-E6 -> 536000 | H6: =IF(G6=0,"NIL",IF(G6>0,"CR","DR")) -> CR
A7: 45435 | B7: PURCHASE | D7: HP 840 G3 I5-6TH 8GB-256 NO CHARGER | F7: 43000 | G7: =G6+F7-E7 -> 579000 | H7: =IF(G7=0,"NIL",IF(G7>0,"CR","DR")) -> CR
A8: 45435 | B8: PURCHASE | D8: HP 840 G3 I5-6TH 8GB-256 NO CHARGER | F8: 43000 | G8: =G7+F8-E8 -> 622000 | H8: =IF(G8=0,"NIL",IF(G8>0,"CR","DR")) -> CR
A9: 45435 | B9: PURCHASE | D9: HP 840 G3 I7-6TH 8GB-256 NO CHARGER | F9: 47000 | G9: =G8+F9-E9 -> 669000 | H9: =IF(G9=0,"NIL",IF(G9>0,"CR","DR")) -> CR
A10: 45437 | B10: PURCHASE | D10: DELL 5420 I5-2ND-4GB-250GB NO CHRG | F10: 18000 | G10: =G9+F10-E10 -> 687000 | H10: =IF(G10=0,"NIL",IF(G10>0,"CR","DR")) -> CR
A11: 45441 | B11: PAYMENT | C11: 47882 | D11: TOSIBA Z30 / HP 840 G6 | E11: 98500 | F11: 0 | G11: =G10+F11-E11 -> 588500 | H11: =IF(G11=0,"NIL",IF(G11>0,"CR","DR")) -> CR
A12: 45445 | B12: PURCHASE | D12: LENOVO T52S CORE I7 8TH 16GB 512GB CHARGER | E12: 0 | F12: 105000 | G12: =G11+F12-E12 -> 693500 | H12: =IF(G12=0,"NIL",IF(G12>0,"CR","DR")) -> CR
A13: 45445 | B13: PURCHASE | D13: HP ELITBOOK 84 0 G3 I5 6TH GEN 8GB 256GB | E13: 0 | F13: 43000 | G13: =G12+F13-E13 -> 736500 | H13: =IF(G13=0,"NIL",IF(G13>0,"CR","DR")) -> CR
A14: 45450 | B14: PAYMENT | C14: 47882 | D14: HP 450 g4 / 5420 | E14: 80000 | F14: 0 | G14: =G13+F14-E14 -> 656500 | H14: =IF(G14=0,"NIL",IF(G14>0,"CR","DR")) -> CR
A15: 45454 | B15: PURCHASE | D15: HP 840 G6 I5-8TH 16GB-256 + CHARGER | F15: 70000 | G15: =G14+F15-E15 -> 726500 | H15: =IF(G15=0,"NIL",IF(G15>0,"CR","DR")) -> CR
A16: 45475 | B16: PAYMENT | C16: 47852 | D16: Dell 3570/7440/5420 | E16: 94500 | G16: =G15+F16-E16 -> 632000 | H16: =IF(G16=0,"NIL",IF(G16>0,"CR","DR")) -> CR
A17: 45477 | B17: PURCHASE | D17: ACER CHOROME BOOK | F17: 12000 | G17: =G16+F17-E17 -> 644000 | H17: =IF(G17=0,"NIL",IF(G17>0,"CR","DR")) -> CR
A18: 45477 | B18: PURCHASE | D18: HP CHOROME BOOK (FOR TASNIM) | F18: 12000 | G18: =G17+F18-E18 -> 656000 | H18: =IF(G18=0,"NIL",IF(G18>0,"CR","DR")) -> CR
A19: 45477 | B19: PURCHASE | D19: DELL 5570 I7-7TH-8-256 2GB CARD NO CHARGER | F19: 53000 | G19: =G18+F19-E19 -> 709000 | H19: =IF(G19=0,"NIL",IF(G19>0,"CR","DR")) -> CR
A20: 45477 | B20: PURCHASE | D20: DELL 7470 I7-6TH-8-256 | F20: 42000 | G20: =G19+F20-E20 -> 751000 | H20: =IF(G20=0,"NIL",IF(G20>0,"CR","DR")) -> CR
A21: 45485 | B21: PAYMENT | D21: DELL 5570(53K) / HP 840 G3 QTY 2(43KX2) | E21: 139000 | G21: =G20+F21-E21 -> 612000 | H21: =IF(G21=0,"NIL",IF(G21>0,"CR","DR")) -> CR
A22: 45485 | B22: PURCHASE | D22: DELL 5570 I7-7TH-8-256 2GB CARD NO CHARGER | F22: 53000 | G22: =G21+F22-E22 -> 665000 | H22: =IF(G22=0,"NIL",IF(G22>0,"CR","DR")) -> CR
A23: 45485 | B23: PURCHASE | D23: HP ELITBOOK 840 G3 I5 6TH GEN 8GB 128GB | F23: 41000 | G23: =G22+F23-E23 -> 706000 | H23: =IF(G23=0,"NIL",IF(G23>0,"CR","DR")) -> CR
A24: 45485 | B24: PURCHASE | D24: HP 840 G3 I7-6TH 8GB-256 NO CHARGER | F24: 47000 | G24: =G23+F24-E24 -> 753000 | H24: =IF(G24=0,"NIL",IF(G24>0,"CR","DR")) -> CR
A25: 45485 | B25: PURCHASE | D25: DELL 3490 I3-7TH-8GB-128SSD+500HDD + CHRG | F25: 34000 | G25: =G24+F25-E25 -> 787000 | H25: =IF(G25=0,"NIL",IF(G25>0,"CR","DR")) -> CR
A26: 45485 | B26: PURCHASE | D26: HP ELITE X2 I5 7TH GEN 8GB 256GB + CHARG | F26: 44000 | G26: =G25+F26-E26 -> 831000 | H26: =IF(G26=0,"NIL",IF(G26>0,"CR","DR")) -> CR
A27: 45494 | B27: RETURN | D27: LENOVO T52S RETURN | E27: 105000 | G27: =G26+F27-E27 -> 726000 | H27: =IF(G27=0,"NIL",IF(G27>0,"CR","DR")) -> CR
A28: 45494 | B28: RETURN | D28: DELL 3490 RETURN | E28: 34000 | G28: =G27+F28-E28 -> 692000 | H28: =IF(G28=0,"NIL",IF(G28>0,"CR","DR")) -> CR
A29: 45503 | B29: PAYMENT | D29: HP 840 G6 / DELL 5570 | E29: 130000 | G29: =G28+F29-E29 -> 562000 | H29: =IF(G29=0,"NIL",IF(G29>0,"CR","DR")) -> CR
A30: 45507 | B30: PURCHASE | D30: LENOVO i5-4TH GEN 8 500 NO CHARGER | F30: 28000 | G30: =G29+F30-E30 -> 590000 | H30: =IF(G30=0,"NIL",IF(G30>0,"CR","DR")) -> CR
A31: 45507 | B31: PURCHASE | D31: DELL 5570 I7-6TH-8-256 2GB CARD NO CHARGER | F31: 53000 | G31: =G30+F31-E31 -> 643000 | H31: =IF(G31=0,"NIL",IF(G31>0,"CR","DR")) -> CR
A32: 45511 | B32: PAYMENT | D32: DELL 5570 / LENOVO T470 | E32: 102000 | G32: =G31+F32-E32 -> 541000 | H32: =IF(G32=0,"NIL",IF(G32>0,"CR","DR")) -> CR
A33: 45512 | B33: PURCHASE | D33: HP 840 G6 | F33: 70000 | G33: =G32+F33-E33 -> 611000 | H33: =IF(G33=0,"NIL",IF(G33>0,"CR","DR")) -> CR
D34: TOTAL BALANCE | E34: =SUM(E6:E33) -> 783000 | F34: =SUM(F6:F33) -> 899000 | G34: =G5+F34-E34 -> 611000 | H34: =IF(G34=0,"NIL",IF(G34>0,"CR","DR")) -> CR

Sheet NAEEM BHI PBM-3 
A1: TASNIM COMPUTERS SALES & SERVICE | J1: PAYABLE HOME
A2: NAEEM BHI PBM ISB LAPTOPS LEDGER
A3: FROM THE MONTH OF JANUARY 2024
A4: DATE | B4: TYPE | C4: REF# | D4: DESCRIPTION | E4: DEBIT | F4: CREDIT | G4: BALANCE
G5: ='NAEEM BHI PBM-2'!G34 -> 611000
A6: 45513 | B6: RETURN | C6: RETURN | D6: LENONVO T540 RETURN | E6: 28000 | G6: =G5+F6-E6 -> 583000 | H6: =IF(G6=0,"NIL",IF(G6>0,"CR","DR")) -> CR
A7: 45519 | B7: PURCHASE | C7: 907032174 | D7: lenovo x1 carbon /chrome book | F7: 59000 | G7: =G6+F7-E7 -> 642000 | H7: =IF(G7=0,"NIL",IF(G7>0,"CR","DR")) -> CR
A8: 45521 | B8: RETURN | C8: RETURN | D8: HP 840 G6 RETURN | E8: 70000 | G8: =G7+F8-E8 -> 572000 | H8: =IF(G8=0,"NIL",IF(G8>0,"CR","DR")) -> CR
A9: 45523 | B9: PAYMENT | C9: PAYMENT | D9: ONLINE PAYMENT THROUGH BOP | E9: 179000 | G9: =G8+F9-E9 -> 393000 | H9: =IF(G9=0,"NIL",IF(G9>0,"CR","DR")) -> CR
A10: 45524 | B10: PURCHASE | C10: PURCHASE | D10: HP CHOROME BOOK | F10: 12000 | G10: =G9+F10-E10 -> 405000 | H10: =IF(G10=0,"NIL",IF(G10>0,"CR","DR")) -> CR
A11: 45537 | B11: PAYMENT | C11: PAYMENT | D11: ONLINE PAYMENT THROUGH BOP | E11: 65000 | G11: =G10+F11-E11 -> 340000 | H11: =IF(G11=0,"NIL",IF(G11>0,"CR","DR")) -> CR
A12: 45544 | B12: PAYMENT | C12: PAYMENT | D12: ONLINE PAYMENT THROUGH BOP | E12: 53000 | G12: =G11+F12-E12 -> 287000 | H12: =IF(G12=0,"NIL",IF(G12>0,"CR","DR")) -> CR
A13: 45558 | B13: PAYMENT | C13: PAYMENT | D13: ONLINE PAYMENT THROUGH BOP | E13: 44000 | G13: =G12+F13-E13 -> 243000 | H13: =IF(G13=0,"NIL",IF(G13>0,"CR","DR")) -> CR
A14: 45576 | B14: PAYMENT | C14: PAYMENT | D14: ONLINE PAYMENT THROUGH BOP | E14: 43000 | G14: =G13+F14-E14 -> 200000 | H14: =IF(G14=0,"NIL",IF(G14>0,"CR","DR")) -> CR
A15: 45579 | B15: PURCHASE | C15: PURCHASE | D15: DELL LATITIDUE 5580 I7-7TH-8-256+CHARGER | E15: 0 | F15: 60000 | G15: =G14+F15-E15 -> 260000 | H15: =IF(G15=0,"NIL",IF(G15>0,"CR","DR")) -> CR
A16: 45584 | B16: PURCHASE | C16: PURCHASE | G16: =G15+F16-E16 -> 260000 | H16: =IF(G16=0,"NIL",IF(G16>0,"CR","DR")) -> CR
A17: 45587 | B17: PAYMENT | C17: PAYMENT | D17: ONLINE PAYMENT THROUGH BOP | E17: 47000 | G17: =G16+F17-E17 -> 213000 | H17: =IF(G17=0,"NIL",IF(G17>0,"CR","DR")) -> CR
A18: 45607 | B18: PAYMENT | C18: PAYMENT | D18: ONLINE PAYMENT THROUGH BOP | E18: 60000 | G18: =G17+F18-E18 -> 153000 | H18: =IF(G18=0,"NIL",IF(G18>0,"CR","DR")) -> CR
A19: 45611 | B19: PAYMENT | C19: PAYMENT | D19: ONLINE PAYMENT THROUGH BOP | E19: 12000 | G19: =G18+F19-E19 -> 141000 | H19: =IF(G19=0,"NIL",IF(G19>0,"CR","DR")) -> CR
A20: 45707 | B20: PAYMENT | C20: PAYMENT | D20: ONLINE PAYMENT THROUGH BOP | E20: 29500 | G20: =G19+F20-E20 -> 111500 | H20: =IF(G20=0,"NIL",IF(G20>0,"CR","DR")) -> CR
G21: =G20+F21-E21 -> 111500 | H21: =IF(G21=0,"NIL",IF(G21>0,"CR","DR")) -> CR
G22: =G21+F22-E22 -> 111500 | H22: =IF(G22=0,"NIL",IF(G22>0,"CR","DR")) -> CR
G23: =G22+F23-E23 -> 111500 | H23: =IF(G23=0,"NIL",IF(G23>0,"CR","DR")) -> CR
G24: =G23+F24-E24 -> 111500 | H24: =IF(G24=0,"NIL",IF(G24>0,"CR","DR")) -> CR
G25: =G24+F25-E25 -> 111500 | H25: =IF(G25=0,"NIL",IF(G25>0,"CR","DR")) -> CR
G26: =G25+F26-E26 -> 111500 | H26: =IF(G26=0,"NIL",IF(G26>0,"CR","DR")) -> CR
G27: =G26+F27-E27 -> 111500 | H27: =IF(G27=0,"NIL",IF(G27>0,"CR","DR")) -> CR
G28: =G27+F28-E28 -> 111500 | H28: =IF(G28=0,"NIL",IF(G28>0,"CR","DR")) -> CR
G29: =G28+F29-E29 -> 111500 | H29: =IF(G29=0,"NIL",IF(G29>0,"CR","DR")) -> CR
G30: =G29+F30-E30 -> 111500 | H30: =IF(G30=0,"NIL",IF(G30>0,"CR","DR")) -> CR
G31: =G30+F31-E31 -> 111500 | H31: =IF(G31=0,"NIL",IF(G31>0,"CR","DR")) -> CR
G32: =G31+F32-E32 -> 111500 | H32: =IF(G32=0,"NIL",IF(G32>0,"CR","DR")) -> CR
... G35: =G34+F35-E35 -> 111500 | H35: =IF(G35=0,"NIL",IF(G35>0,"CR","DR")) -> CR
D36: TOTAL BALANCE | E36: =SUM(E6:E35) -> 630500 | F36: =SUM(F6:F35) -> 131000 | G36: =G5+F36-E36 -> 111500 | H36: =IF(G36=0,"NIL",IF(G36>0,"CR","DR")) -> CR

Sheet NAEEM BHI PBM ISB LAPTOPS 1 
A1: TASNIM COMPUTERS SALES & SERVICE | J1: PAYABLE HOME
A2: NAEEM BHI PBM ISB LAPTOPS LEDGER
A3: FROM THE MONTH OF APRIL 2026
A4: DATE | B4: TYPE | C4: REF# | D4: DESCRIPTION | E4: DEBIT | F4: CREDIT | G4: BALANCE
A5: 46078 | B5: PURCHASE | C5: LAPTOPS | D5: PURCHASE LAPTOPS QTY 09 | G5: 502000
A6: 46110 | B6: PAYMENT | C6: CASH | D6: CASH BY HAND AT HOME | E6: 90000 | G6: =G5+F6-E6 -> 412000 | H6: =IF(G6=0,"NIL",IF(G6>0,"CR","DR")) -> CR
A7: 46110 | B7: PURCHASE | C7: LAPTOP/SSD | D7: laptop/ssd | F7: 10450 | G7: =G6+F7-E7 -> 422450 | H7: =IF(G7=0,"NIL",IF(G7>0,"CR","DR")) -> CR
A8: 46113 | B8: PURCHASE | C8: LAPTOP | D8: HP 840 I5 10TH GEN 8/256 | F8: 65000 | G8: =G7+F8-E8 -> 487450 | H8: =IF(G8=0,"NIL",IF(G8>0,"CR","DR")) -> CR
A9: 46113 | B9: PURCHASE | C9: LAPTOP | D9: DELL 7470 I5 6TH 8/256 | F9: 35000 | G9: =G8+F9-E9 -> 522450 | H9: =IF(G9=0,"NIL",IF(G9>0,"CR","DR")) -> CR
A10: 46119 | B10: PURCHASE | C10: CHARGER | D10: LAPTOP CHARGER | F10: 60200 | G10: =G9+F10-E10 -> 582650 | H10: =IF(G10=0,"NIL",IF(G10>0,"CR","DR")) -> CR
A11: 46119 | B11: PURCHASE | C11: LAPTOP | D11: LENOVO T490S I5 8TH 8/256 | F11: 45000 | G11: =G10+F11-E11 -> 627650 | H11: =IF(G11=0,"NIL",IF(G11>0,"CR","DR")) -> CR
A12: 46119 | B12: PAYMENT | C12: CASH | D12: ONLINE MEEZAN BANK NAEEM SIR | E12: 90000 | G12: =G11+F12-E12 -> 537650 | H12: =IF(G12=0,"NIL",IF(G12>0,"CR","DR")) -> CR
A13: 45389 | B13: PAYMENT | C13: CASH | D13: ONLINE MEEZAN BANK NAEEM SIR | E13: 50000 | G13: =G12+F13-E13 -> 487650 | H13: =IF(G13=0,"NIL",IF(G13>0,"CR","DR")) -> CR
A14: 46121 | B14: PURCHASE | C14: LAPTOP | D14: LENOVO L380 I5 8TH 8GB 256 | F14: 44000 | G14: =G13+F14-E14 -> 531650 | H14: =IF(G14=0,"NIL",IF(G14>0,"CR","DR")) -> CR
A15: 46121 | B15: PURCHASE | C15: LAPTOP | D15: LENOVO T460 I5 6TH 8GB 256GB | F15: 35000 | G15: =G14+F15-E15 -> 566650 | H15: =IF(G15=0,"NIL",IF(G15>0,"CR","DR")) -> CR
A16: 46121 | B16: PURCHASE | C16: LAPTOP | D16: PRINTER CABLE 3M | F16: 450 | G16: =G15+F16-E16 -> 567100 | H16: =IF(G16=0,"NIL",IF(G16>0,"CR","DR")) -> CR
A17: 46121 | B17: PURCHASE | C17: LAPTOP | D17: PRINTER CABLE 1.5 QTY 270*5 | F17: 1350 | G17: =G16+F17-E17 -> 568450 | H17: =IF(G17=0,"NIL",IF(G17>0,"CR","DR")) -> CR
A18: 46128 | B18: PURCHASE | C18: LAPTOP | D18: HP 840 I5 8TH 16/512 | F18: 69000 | G18: =G17+F18-E18 -> 637450 | H18: =IF(G18=0,"NIL",IF(G18>0,"CR","DR")) -> CR
A19: 46128 | B19: PURCHASE | C19: LAPTOP | D19: HP 840 I5 8TH 16/512 | F19: 69000 | G19: =G18+F19-E19 -> 706450 | H19: =IF(G19=0,"NIL",IF(G19>0,"CR","DR")) -> CR
A20: 46128 | B20: PURCHASE | C20: CHARGER | D20: LENOVO TYPE-C CHARGER | F20: 4400 | G20: =G19+F20-E20 -> 710850 | H20: =IF(G20=0,"NIL",IF(G20>0,"CR","DR")) -> CR
A21: 46132 | B21: PURCHASE | C21: LAPTOP | D21: HP 840 I7 8TH 16/512 | F21: 74000 | G21: =G20+F21-E21 -> 784850 | H21: =IF(G21=0,"NIL",IF(G21>0,"CR","DR")) -> CR
A22: 46132 | B22: PURCHASE | C22: LAPTOP | D22: HP 840 I7 8TH 16/512 | F22: 74000 | G22: =G21+F22-E22 -> 858850 | H22: =IF(G22=0,"NIL",IF(G22>0,"CR","DR")) -> CR
A23: 46132 | B23: PURCHASE | C23: RAM | D23: LAPTOP RAM DDR 4 8GB | F23: 8000 | G23: =G22+F23-E23 -> 866850 | H23: =IF(G23=0,"NIL",IF(G23>0,"CR","DR")) -> CR
A24: 46137 | B24: RETURNE | C24: LAPTOP | D24: DELL 5491H I5 8TH 8GB 256 | E24: 44000 | G24: =G23+F24-E24 -> 822850 | H24: =IF(G24=0,"NIL",IF(G24>0,"CR","DR")) -> CR
A25: 46137 | B25: RETURNE | C25: LAPTOP | D25: DELL 5491H I5 8TH 8GB 256 | E25: 45000 | G25: =G24+F25-E25 -> 777850 | H25: =IF(G25=0,"NIL",IF(G25>0,"CR","DR")) -> CR
A26: 46141 | B26: RETURNE | C26: LAPTOP | D26: DELL 5501 I5 9TH 8GB 256 | E26: 60000 | G26: =G25+F26-E26 -> 717850 | H26: =IF(G26=0,"NIL",IF(G26>0,"CR","DR")) -> CR
A27: 46136 | B27: PAYMENT | C27: CASH | D27: ONLINE MEEZAN BANK NAEEM SIR | E27: 200000 | G27: =G26+F27-E27 -> 517850 | H27: =IF(G27=0,"NIL",IF(G27>0,"CR","DR")) -> CR
A28: 46138 | B28: PURCHASE | C28: LAPTOP | D28: DELL 5400 I5 8TH 8GB 256GB | F28: 44000 | G28: =G27+F28-E28 -> 561850 | H28: =IF(G28=0,"NIL",IF(G28>0,"CR","DR")) -> CR
A29: 46138 | B29: PURCHASE | C29: LAPTOP | D29: LENOVO T480 I5 8TH 8GB 256GB | F29: 44000 | G29: =G28+F29-E29 -> 605850 | H29: =IF(G29=0,"NIL",IF(G29>0,"CR","DR")) -> CR
A30: 46138 | B30: PURCHASE | C30: LAPTOP | D30: DELL LATITUDE 7440 I5 6TH 8GB 256GB | F30: 35000 | G30: =G29+F30-E30 -> 640850 | H30: =IF(G30=0,"NIL",IF(G30>0,"CR","DR")) -> CR
A31: 46138 | B31: PURCHASE | C31: LAPTOP | D31: HP 840 G5 I5 8TH 8GB 256GB | F31: 62000 | G31: =G30+F31-E31 -> 702850 | H31: =IF(G31=0,"NIL",IF(G31>0,"CR","DR")) -> CR
A32: 46138 | B32: PURCHASE | C32: LAPTOP | D32: LENOVO L490 I7 8TH 8GB 256GB | F32: 47000 | G32: =G31+F32-E32 -> 749850 | H32: =IF(G32=0,"NIL",IF(G32>0,"CR","DR")) -> CR
A33: 46138 | B33: PURCHASE | C33: RAM | D33: L.P RAM DDR 3 4GB | F33: 6000 | G33: =G32+F33-E33 -> 755850 | H33: =IF(G33=0,"NIL",IF(G33>0,"CR","DR")) -> CR
A34: 46138 | B34: PURCHASE | C34: LP CHARGER | D34: LENOVO CHARGER TYPE C QTY 2 | F34: 4400 | G34: =G33+F34-E34 -> 760250 | H34: =IF(G34=0,"NIL",IF(G34>0,"CR","DR")) -> CR
G35: =G34+F35-E35 -> 760250 | H35: =IF(G35=0,"NIL",IF(G35>0,"CR","DR")) -> CR
D36: TOTAL BALANCE | E36: =SUM(E6:E35) -> 579000 | F36: =SUM(F6:F35) -> 837250 | G36: =G5+F36-E36 -> 760250 | H36: =IF(G36=0,"NIL",IF(G36>0,"CR","DR")) -> CR

Sheet NAEEM BHI PBM ISB LAPTOPS 2
A1: TASNIM COMPUTERS SALES & SERVICE | J1: PAYABLE HOME
A2: NAEEM BHI PBM ISB LAPTOPS LEDGER
A3: FROM THE MONTH OF APRIL 2026
A4: DATE | B4: TYPE | C4: REF# | D4: DESCRIPTION | E4: DEBIT | F4: CREDIT | G4: BALANCE
G5: 760250
A6: 46142 | B6: PAYMENT | C6: CASH | D6: ONLINE MEEZAN BANK NAEEM SIR | E6: 40000 | G6: =G5+F6-E6 -> 720250 | H6: =IF(G6=0,"NIL",IF(G6>0,"CR","DR")) -> CR
A7: 46118 | B7: RETURNE | C7: LAPTOP | D7: LENOVO YOGA G5 I7 10TH 16/512 | E7: 100000 | G7: =G6+F7-E7 -> 620250 | H7: =IF(G7=0,"NIL",IF(G7>0,"CR","DR")) -> CR
A8: 46148 | B8: PURCHASE | C8: LAPTOP | D8: DELL LATITUDE 7470 I5 6TH 8/256GB | F8: 37000 | G8: =G7+F8-E8 -> 657250 | H8: =IF(G8=0,"NIL",IF(G8>0,"CR","DR")) -> CR
A9: 46148 | B9: PURCHASE | C9: LAPTOP | D9: LENOVO T470S I7 6TH 8GB /256GB | F9: 40000 | G9: =G8+F9-E9 -> 697250 | H9: =IF(G9=0,"NIL",IF(G9>0,"CR","DR")) -> CR
A10: 46153 | B10: PAYMENT | C10: CASH | D10: ONLINE MEEZAN BANK NAEEM SIR | E10: 130000 | G10: =G9+F10-E10 -> 567250 | H10: =IF(G10=0,"NIL",IF(G10>0,"CR","DR")) -> CR
A11: 46162 | B11: PAYMENT | C11: CASH | D11: ONLINE MEEZAN BANK NAEEM SIR | E11: 65000 | G11: =G10+F11-E11 -> 502250 | H11: =IF(G11=0,"NIL",IF(G11>0,"CR","DR")) -> CR
A12: 46184 | B12: PAYMENT | C12: CASH | D12: 7470-L490-T480 | E12: 128000 | G12: =G11+F12-E12 -> 374250 | H12: =IF(G12=0,"NIL",IF(G12>0,"CR","DR")) -> CR
A13: 46185 | B13: PURCHASE | C13: LAPTOP | D13: HP 840 G7 I5 10TH GEN 16GB/256GB | F13: 73000 | G13: =G12+F13-E13 -> 447250 | H13: =IF(G13=0,"NIL",IF(G13>0,"CR","DR")) -> CR
A14: 46185 | B14: PURCHASE | C14: LAPTOP | D14: LENOVO T470S I7 6TH 8GB /256GB | F14: 39000 | G14: =G13+F14-E14 -> 486250 | H14: =IF(G14=0,"NIL",IF(G14>0,"CR","DR")) -> CR
A15: 46185 | B15: PURCHASE | C15: LAPTOP | D15: LENOVO T490S I5 8TH 8GB/256GB | F15: 44000 | G15: =G14+F15-E15 -> 530250 | H15: =IF(G15=0,"NIL",IF(G15>0,"CR","DR")) -> CR
A16: 46175 | B16: PAYMENT | C16: CASH | D16: ONLINE MEEZAN BANK NAEEM SIR | E16: 39000 | G16: =G15+F16-E16 -> 491250 | H16: =IF(G16=0,"NIL",IF(G16>0,"CR","DR")) -> CR
A17: 46207 | B17: PURCHASE | C17: LAPTOP | D17: LENOVO T470S I5 6TH 8GB /256GB | F17: 35000 | G17: =G16+F17-E17 -> 526250 | H17: =IF(G17=0,"NIL",IF(G17>0,"CR","DR")) -> CR
A18: 46207 | B18: PURCHASE | C18: LAPTOP | D18: LENOVO T460S I5 7TH 8GB / 256GB | F18: 38000 | G18: =G17+F18-E18 -> 564250 | H18: =IF(G18=0,"NIL",IF(G18>0,"CR","DR")) -> CR
A19: 46207 | B19: PURCHASE | C19: LAPTOP | D19: LENOVO L490 I78TH 8GB / 258GB | F19: 46000 | G19: =G18+F19-E19 -> 610250 | H19: =IF(G19=0,"NIL",IF(G19>0,"CR","DR")) -> CR
A20: 46207 | B20: PURCHASE | C20: LAPTOP | D20: LENOVO YOGA L389 I5 8TH 8GB 256GB | F20: 46000 | G20: =G19+F20-E20 -> 656250 | H20: =IF(G20=0,"NIL",IF(G20>0,"CR","DR")) -> CR
A21: 46207 | B21: PURCHASE | C21: LAPTOP | D21: HP PROBOOK 440 I5 7TH 8GB 256GB | F21: 39000 | G21: =G20+F21-E21 -> 695250 | H21: =IF(G21=0,"NIL",IF(G21>0,"CR","DR")) -> CR
A22: 46209 | B22: PAYMENT | C22: CASH | D22: ONLINE MEEZAN BANK NAEEM SIR | E22: 50000 | G22: =G21+F22-E22 -> 645250 | H22: =IF(G22=0,"NIL",IF(G22>0,"CR","DR")) -> CR
A23: 46213 | B23: PAYMENT | C23: CASH | D23: ONLINE MEEZAN BANK NAEEM SIR | E23: 49000 | G23: =G22+F23-E23 -> 596250 | H23: =IF(G23=0,"NIL",IF(G23>0,"CR","DR")) -> CR
A24: 46252 | B24: PURCHASE | C24: SSD | D24: 128GB 256GB BREAKABLE | F24: 18500 | G24: =G23+F24-E24 -> 614750 | H24: =IF(G24=0,"NIL",IF(G24>0,"CR","DR")) -> CR
A25: 46256 | B25: PURCHASE | C25: LAPTOP | D25: HP ELITEBOOK G8 I5 11TH 16GB/256 | F25: 75000 | G25: =G24+F25-E25 -> 689750 | H25: =IF(G25=0,"NIL",IF(G25>0,"CR","DR")) -> CR
A26: 46256 | B26: PURCHASE | C26: LAPTOP | D26: HP ELITEBOOK G9 I5 12TH 16GB/256GB | F26: 11000 | G26: =G25+F26-E26 -> 700750 | H26: =IF(G26=0,"NIL",IF(G26>0,"CR","DR")) -> CR
A27: 46256 | B27: PAYMENT | C27: CASH | D27: ONLINE MEEZAN BANK NAEEM SIR | E27: 345000 | G27: =G26+F27-E27 -> 355750 | H27: =IF(G27=0,"NIL",IF(G27>0,"CR","DR")) -> CR
G28: =G27+F28-E28 -> 355750 | H28: =IF(G28=0,"NIL",IF(G28>0,"CR","DR")) -> CR
G29: =G28+F29-E29 -> 355750 | H29: =IF(G29=0,"NIL",IF(G29>0,"CR","DR")) -> CR
G30: =G29+F30-E30 -> 355750 | H30: =IF(G30=0,"NIL",IF(G30>0,"CR","DR")) -> CR
G31: =G30+F31-E31 -> 355750 | H31: =IF(G31=0,"NIL",IF(G31>0,"CR","DR")) -> CR
G32: =G31+F32-E32 -> 355750 | H32: =IF(G32=0,"NIL",IF(G32>0,"CR","DR")) -> CR
G33: =G32+F33-E33 -> 355750 | H33: =IF(G33=0,"NIL",IF(G33>0,"CR","DR")) -> CR
G34: =G33+F34-E34 -> 355750 | H34: =IF(G34=0,"NIL",IF(G34>0,"CR","DR")) -> CR
G35: =G34+F35-E35 -> 355750 | H35: =IF(G35=0,"NIL",IF(G35>0,"CR","DR")) -> CR
D36: TOTAL BALANCE | E36: =SUM(E6:E35) -> 946000 | F36: =SUM(F6:F35) -> 541500 | G36: =G5+F36-E36 -> 355750 | H36: =IF(G36=0,"NIL",IF(G36>0,"CR","DR")) -> CR

Sheet  ZAFAR & SONS RWP 1
A1: TASNIM COMPUTERS SALES & SERVICE | J1: PAYABLE HOME
A2: ZAFAR & SONS RWP LEDGER
A3: FROM THE MONTH OF JANUARY 2024
A4: DATE | B4: TYPE | C4: REF# | D4: DESCRIPTION | E4: DEBIT | F4: CREDIT | G4: BALANCE
A6: 45296 | B6: PURCHASE | C6: BILL# 0140 | D6: SYSTEMS /LCD/GRAPHIC CARD | F6: 130900 | G6: =G5+F6-E6 -> 130900 | H6: =IF(G6=0,"NIL",IF(G6>0,"CR","DR")) -> CR
A7: 45299 | B7: PAYMENT | C7: 890968438 | D7: ONLINE PAYMENT THROUGH BANK | E7: 50000 | G7: =G6+F7-E7 -> 80900 | H7: =IF(G7=0,"NIL",IF(G7>0,"CR","DR")) -> CR
A8: 45312 | B8: PAYMENT | C8: 897169914 | D8: ONLINE PAYMENT THROUGH BANK | E8: 30900 | G8: =G7+F8-E8 -> 50000 | H8: =IF(G8=0,"NIL",IF(G8>0,"CR","DR")) -> CR
A9: 45315 | B9: PAYMENT | C9: CASH | D9: CASH BY HAND | E9: 100000 | F9: 50000 | G9: =G8+F9-E9 -> 0 | H9: =IF(G9=0,"NIL",IF(G9>0,"CR","DR")) -> NIL
A10: 45315 | B10: PURCHASE | C10: BILL# 0210 | D10: LEDS PURCHASED | F10: 373000 | G10: =G9+F10-E10 -> 373000 | H10: =IF(G10=0,"NIL",IF(G10>0,"CR","DR")) -> CR
A11: 45320 | B11: PAYMENT | C11: 900487264 | D11: ONLINE PAYMENT THROUGH BANK | E11: 45000 | G11: =G10+F11-E11 -> 328000 | H11: =IF(G11=0,"NIL",IF(G11>0,"CR","DR")) -> CR
A12: 45331 | B12: PAYMENT | C12: 907032174 | D12: ONLINE PAYMENT THROUGH BANK | E12: 100000 | G12: =G11+F12-E12 -> 228000 | H12: =IF(G12=0,"NIL",IF(G12>0,"CR","DR")) -> CR
A13: 45339 | B13: PAYMENT | C13: 4372 | D13: ONLINE PAYMENT THROUGH BANK | E13: 100000 | G13: =G12+F13-E13 -> 128000 | H13: =IF(G13=0,"NIL",IF(G13>0,"CR","DR")) -> CR
A14: 45339 | B14: PURCHASE | C14: BILL# 0408 | D14: SYSTEMS /LCD/GRAPHIC CARD | F14: 249000 | G14: =G13+F14-E14 -> 377000 | H14: =IF(G14=0,"NIL",IF(G14>0,"CR","DR")) -> CR
A15: 45339 | B15: PURCHASE | C15: BILL# 0407 | D15: GRAPHIC CARD LED | F15: 177800 | G15: =G14+F15-E15 -> 554800 | H15: =IF(G15=0,"NIL",IF(G15>0,"CR","DR")) -> CR
A16: 45354 | B16: PAYMENT | C16: 918735228 | D16: ONLINE PAYMENT THROUGH BANK | E16: 104800 | G16: =G15+F16-E16 -> 450000 | H16: =IF(G16=0,"NIL",IF(G16>0,"CR","DR")) -> CR
A17: 45355 | B17: PURCHASE | C17: BILL# 0513 | D17: HDD PURCHED | F17: 5200 | G17: =G16+F17-E17 -> 455200 | H17: =IF(G17=0,"NIL",IF(G17>0,"CR","DR")) -> CR
A18: 45364 | B18: PAYMENT | C18: 283496338 | D18: ONLINE PAYMENT THROUGH BANK | E18: 40500 | G18: =G17+F18-E18 -> 414700 | H18: =IF(G18=0,"NIL",IF(G18>0,"CR","DR")) -> CR
A19: 45367 | B19: PAYMENT | C19: CASH | D19: CASH BY HAND | E19: 60000 | G19: =G18+F19-E19 -> 354700 | H19: =IF(G19=0,"NIL",IF(G19>0,"CR","DR")) -> CR
A20: 45367 | B20: PURCHASE | C20: BILL# 0482 | D20: LED / SYSTEMS | F20: 260500 | G20: =G19+F20-E20 -> 615200 | H20: =IF(G20=0,"NIL",IF(G20>0,"CR","DR")) -> CR
A21: 45367 | B21: PURCHASE | C21: BILL# 0484 | D21: LED / SYSTEMS | F21: 37500 | G21: =G20+F21-E21 -> 652700 | H21: =IF(G21=0,"NIL",IF(G21>0,"CR","DR")) -> CR
A22: 45375 | B22: PAYMENT | C22: 907032174 | D22: ONLINE PAYMENT THROUGH BANK | E22: 52700 | G22: =G21+F22-E22 -> 600000 | H22: =IF(G22=0,"NIL",IF(G22>0,"CR","DR")) -> CR
A23: 45390 | B23: PAYMENT | C23: 907032174 | D23: ONLINE PAYMENT THROUGH BANK | E23: 100000 | G23: =G22+F23-E23 -> 500000 | H23: =IF(G23=0,"NIL",IF(G23>0,"CR","DR")) -> CR
A24: 45399 | B24: PAYMENT | C24: 907032174 | D24: ONLINE PAYMENT THROUGH BANK | E24: 30000 | G24: =G23+F24-E24 -> 470000 | H24: =IF(G24=0,"NIL",IF(G24>0,"CR","DR")) -> CR
A25: 45406 | B25: PURCHASE | C25: Bill#0752 | D25: HDD/ DDR 3 | F25: 17000 | G25: =G24+F25-E25 -> 487000 | H25: =IF(G25=0,"NIL",IF(G25>0,"CR","DR")) -> CR
A26: 45413 | B26: PAYMENT | C26: 907032174 | D26: ONLINE PAYMENT THROUGH BANK | E26: 80000 | G26: =G25+F26-E26 -> 407000 | H26: =IF(G26=0,"NIL",IF(G26>0,"CR","DR")) -> CR
A27: 45425 | B27: PAYMENT | C27: 957410210 | D27: ONLINE PAYMENT THROUGH BANK | E27: 57000 | G27: =G26+F27-E27 -> 350000 | H27: =IF(G27=0,"NIL",IF(G27>0,"CR","DR")) -> CR
A28: 45434 | B28: PAYMENT | C28: 907032174 | D28: ONLINE PAYMENT THROUGH BANK | E28: 55500 | G28: =G27+F28-E28 -> 294500 | H28: =IF(G28=0,"NIL",IF(G28>0,"CR","DR")) -> CR
A29: 45437 | B29: PURCHASE | C29: BILL# 1045 | D29: SSD 128GB QTY-5 | F29: 13500 | G29: =G28+F29-E29 -> 308000 | H29: =IF(G29=0,"NIL",IF(G29>0,"CR","DR")) -> CR
A30: 45443 | B30: PAYMENT | C30: 907032174 | D30: ONLINE PAYMENT THROUGH BANK | E30: 55000 | G30: =G29+F30-E30 -> 253000 | H30: =IF(G30=0,"NIL",IF(G30>0,"CR","DR")) -> CR
A31: 45455 | B31: PAYMENT | C31: 90528791 | D31: ONLINE PAYMENT THROUGH BANK | E31: 53000 | G31: =G30+F31-E31 -> 200000 | H31: =IF(G31=0,"NIL",IF(G31>0,"CR","DR")) -> CR
A32: 45474 | B32: PAYMENT | C32: 907032174 | D32: ONLINE PAYMENT THROUGH BANK | E32: 50000 | G32: =G31+F32-E32 -> 150000 | H32: =IF(G32=0,"NIL",IF(G32>0,"CR","DR")) -> CR
A33: 45485 | B33: PAYMENT | C33: 907032174 | D33: ONLINE PAYMENT THROUGH BANK | E33: 75000 | G33: =G32+F33-E33 -> 75000 | H33: =IF(G33=0,"NIL",IF(G33>0,"CR","DR")) -> CR
A34: 45493 | B34: PURCHASE | C34: BILL#1395 | D34: PURCHASING | F34: 72200 | G34: =G33+F34-E34 -> 147200 | H34: =IF(G34=0,"NIL",IF(G34>0,"CR","DR")) -> CR
A35: 45502 | B35: PAYMENT | C35: 907032174 | D35: ONLINE PAYMENT THROUGH BANK | E35: 27200 | G35: =G34+F35-E35 -> 120000 | H35: =IF(G35=0,"NIL",IF(G35>0,"CR","DR")) -> CR
D36: TOTAL BALANCE | E36: =SUM(E6:E35) -> 1266600 | F36: =SUM(F6:F35) -> 1386600 | G36: =G5+F36-E36 -> 120000 | H36: =IF(G36=0,"NIL",IF(G36>0,"CR","DR")) -> CR

Sheet  ZAFAR & SONS RWP 2
A1: TASNIM COMPUTERS SALES & SERVICE | J1: PAYABLE HOME
A2: ZAFAR & SONS RWP LEDGER
A3: FROM THE MONTH OF JANUARY 2024
A4: DATE | B4: TYPE | C4: REF# | D4: DESCRIPTION | E4: DEBIT | F4: CREDIT | G4: BALANCE
G5: =' ZAFAR & SONS RWP 1'!G36 -> 120000
A6: 45512 | B6: PAYMENT | D6: BOP ONLINE PAYMENT | E6: 60000 | F6: 0 | G6: =G5+F6-E6 -> 60000 | H6: =IF(G6=0,"NIL",IF(G6>0,"CR","DR")) -> CR
A7: 45514 | B7: PURCHASE | C7: BILL# 1739 | D7: PURCHASING FROM RWP | E7: 0 | F7: 140000 | G7: =G6+F7-E7 -> 200000 | H7: =IF(G7=0,"NIL",IF(G7>0,"CR","DR")) -> CR
A8: 45526 | B8: PAYMENT | C8: PAYMENT | D8: ONLINE BOP | E8: 40000 | G8: =G7+F8-E8 -> 160000 | H8: =IF(G8=0,"NIL",IF(G8>0,"CR","DR")) -> CR
A9: 45541 | B9: PAYMENT | C9: PAYMENT | D9: ONLINE BOP | E9: 50000 | G9: =G8+F9-E9 -> 110000 | H9: =IF(G9=0,"NIL",IF(G9>0,"CR","DR")) -> CR
A10: 45565 | B10: PAYMENT | C10: PAYMENT | D10: ONLINE BOP | E10: 50000 | G10: =G9+F10-E10 -> 60000 | H10: =IF(G10=0,"NIL",IF(G10>0,"CR","DR")) -> CR
A11: 45572 | B11: ADJUSTMENT | C11: PAYMENT | D11: HP Z40 V5 | E11: 42500 | G11: =G10+F11-E11 -> 17500 | H11: =IF(G11=0,"NIL",IF(G11>0,"CR","DR")) -> CR
A12: 45572 | B12: PURCHASE | C12: BILL#2068 | D12: PURCHASING FROM RWP | F12: =172300+14000 -> 186300 | G12: =G11+F12-E12 -> 203800 | H12: =IF(G12=0,"NIL",IF(G12>0,"CR","DR")) -> CR
A13: 45576 | B13: PAYMENT | C13: PAYMENT | D13: ONLINE BOP | E13: 30000 | G13: =G12+F13-E13 -> 173800 | H13: =IF(G13=0,"NIL",IF(G13>0,"CR","DR")) -> CR
A14: 45583 | B14: PAYMENT | C14: PAYMENT | D14: ONLINE BOP | E14: 23800 | G14: =G13+F14-E14 -> 150000 | H14: =IF(G14=0,"NIL",IF(G14>0,"CR","DR")) -> CR
A15: 45593 | B15: PURCHASE | C15: BILL#2122 | D15: PURCHASING FROM RWP | F15: 107200 | G15: =G14+F15-E15 -> 257200 | H15: =IF(G15=0,"NIL",IF(G15>0,"CR","DR")) -> CR
A16: 45593 | B16: PURCHASE | C16: BILL#2122 | D16: DDR 2 2GB | F16: 3200 | G16: =G15+F16-E16 -> 260400 | H16: =IF(G16=0,"NIL",IF(G16>0,"CR","DR")) -> CR
A17: 45594 | B17: PAYMENT | C17: PAYMENT | D17: ONLINE BOP | E17: 60400 | G17: =G16+F17-E17 -> 200000 | H17: =IF(G17=0,"NIL",IF(G17>0,"CR","DR")) -> CR
A18: 45602 | B18: PAYMENT | C18: PAYMENT | D18: ONLINE BOP | E18: 50000 | G18: =G17+F18-E18 -> 150000 | H18: =IF(G18=0,"NIL",IF(G18>0,"CR","DR")) -> CR
A19: 45611 | B19: PAYMENT | C19: PAYMENT | D19: ONLINE BOP | E19: 30000 | G19: =G18+F19-E19 -> 120000 | H19: =IF(G19=0,"NIL",IF(G19>0,"CR","DR")) -> CR
A20: 45612 | B20: PURCHASE | C20: BILL#2184 | D20: PURCHASING FROM RWP | F20: 41500 | G20: =G19+F20-E20 -> 161500 | H20: =IF(G20=0,"NIL",IF(G20>0,"CR","DR")) -> CR
A21: 45614 | B21: PAYMENT | C21: PAYMENT | D21: ONLINE BOP | E21: 51500 | G21: =G20+F21-E21 -> 110000 | H21: =IF(G21=0,"NIL",IF(G21>0,"CR","DR")) -> CR
A22: 45629 | B22: PURCHASE | C22: BILL# 2234 | D22: I5-6TH GEN 16GB 128 500GB | E22: 0 | F22: 37000 | G22: =G21+F22-E22 -> 147000 | H22: =IF(G22=0,"NIL",IF(G22>0,"CR","DR")) -> CR
A23: 45642 | B23: PAYMENT | C23: PAYMENT | D23: ONLINE BOP | E23: 50000 | G23: =G22+F23-E23 -> 97000 | H23: =IF(G23=0,"NIL",IF(G23>0,"CR","DR")) -> CR
A24: 45661 | B24: PURCHASE | C24: BILL#2328 | D24: PURCHASING FROM RWP | F24: 77100 | G24: =G23+F24-E24 -> 174100 | H24: =IF(G24=0,"NIL",IF(G24>0,"CR","DR")) -> CR
A25: 45661 | B25: PAYMENT | C25: PAYMENT | D25: ONLINE BOP | E25: 100000 | G25: =G24+F25-E25 -> 74100 | H25: =IF(G25=0,"NIL",IF(G25>0,"CR","DR")) -> CR
A26: 45681 | B26: PAYMENT | C26: PAYMENT | D26: ONLINE BOP | E26: 24100 | G26: =G25+F26-E26 -> 50000 | H26: =IF(G26=0,"NIL",IF(G26>0,"CR","DR")) -> CR
A27: 45687 | B27: PURCHASE | C27: BILL#2328 | D27: PURCHASING FROM RWP | F27: 25500 | G27: =G26+F27-E27 -> 75500 | H27: =IF(G27=0,"NIL",IF(G27>0,"CR","DR")) -> CR
A28: 45694 | C28: PAYMENT | D28: ONLINE BOP | E28: 30500 | G28: =G27+F28-E28 -> 45000 | H28: =IF(G28=0,"NIL",IF(G28>0,"CR","DR")) -> CR
A29: 45701 | B29: PURCHASE | C29: BILL#2454 | D29: PURCHASING FROM RWP | F29: 146200 | G29: =G28+F29-E29 -> 191200 | H29: =IF(G29=0,"NIL",IF(G29>0,"CR","DR")) -> CR
A30: 45732 | B30: PAYMENT | C30: PAYMENT | D30: ONLINE BOP | E30: 51200 | G30: =G29+F30-E30 -> 140000 | H30: =IF(G30=0,"NIL",IF(G30>0,"CR","DR")) -> CR
A31: 45744 | B31: PAYMENT | C31: PAYMENT | D31: ONLINE BOP | E31: 50000 | G31: =G30+F31-E31 -> 90000 | H31: =IF(G31=0,"NIL",IF(G31>0,"CR","DR")) -> CR
A32: 45759 | B32: PURCHASE | C32: BILL#2588 | D32: PURCHASING FROM RWP | F32: 121550 | G32: =G31+F32-E32 -> 211550 | H32: =IF(G32=0,"NIL",IF(G32>0,"CR","DR")) -> CR
A33: 45759 | B33: PURCHASE | C33: BILL#2509 | D33: PURCHASING FROM RWP | F33: 56700 | G33: =G32+F33-E33 -> 268250 | H33: =IF(G33=0,"NIL",IF(G33>0,"CR","DR")) -> CR
A34: 45763 | B34: PAYMENT | C34: PAYMENT | D34: ONLINE BOP | E34: 68250 | G34: =G33+F34-E34 -> 200000 | H34: =IF(G34=0,"NIL",IF(G34>0,"CR","DR")) -> CR
G35: =G34+F35-E35 -> 200000 | H35: =IF(G35=0,"NIL",IF(G35>0,"CR","DR")) -> CR
D36: TOTAL BALANCE | E36: =SUM(E6:E35) -> 862250 | F36: =SUM(F6:F35) -> 942250 | G36: =G5+F36-E36 -> 200000 | H36: =IF(G36=0,"NIL",IF(G36>0,"CR","DR")) -> CR

Sheet ZAFAR & SONS RWP 3 
A1: TASNIM COMPUTERS SALES & SERVICE | J1: PAYABLE HOME
A2: ZAFAR & SONS RWP LEDGER
A3: FROM THE MONTH OF JANUARY 2024
A4: DATE | B4: TYPE | C4: REF# | D4: DESCRIPTION | E4: DEBIT | F4: CREDIT | G4: BALANCE
G5: 200000
A6: 45769 | B6: PAYMENT | C6: PAYMENT | D6: BOP ONLINE PAYMENT | E6: 40000 | G6: =G5+F6-E6 -> 160000 | H6: =IF(G6=0,"NIL",IF(G6>0,"CR","DR")) -> CR
A7: 45787 | B7: PURCHASE | C7: BILL#2609 | D7: PURCHASING FROM RWP | F7: 11000 | G7: =G6+F7-E7 -> 171000 | H7: =IF(G7=0,"NIL",IF(G7>0,"CR","DR")) -> CR
A8: 45787 | B8: PURCHASE | C8: BILL#2633 | D8: PURCHASING FROM RWP | F8: 94100 | G8: =G7+F8-E8 -> 265100 | H8: =IF(G8=0,"NIL",IF(G8>0,"CR","DR")) -> CR
A9: 45787 | B9: PAYMENT | C9: PAYMENT | D9: BOP ONLINE PAYMENT | E9: 65100 | G9: =G8+F9-E9 -> 200000 | H9: =IF(G9=0,"NIL",IF(G9>0,"CR","DR")) -> CR
A10: 45797 | B10: PAYMENT | C10: PAYMENT | D10: BOP ONLINE PAYMENT | E10: 40000 | G10: =G9+F10-E10 -> 160000 | H10: =IF(G10=0,"NIL",IF(G10>0,"CR","DR")) -> CR
A11: 45800 | B11: PAYMENT | C11: PAYMENT | D11: BOP ONLINE PAYMENT | E11: 50000 | G11: =G10+F11-E11 -> 110000 | H11: =IF(G11=0,"NIL",IF(G11>0,"CR","DR")) -> CR
A12: 45802 | B12: PURCHASE | C12: BILL#2661 | D12: PURCHASING FROM RWP | F12: 191150 | G12: =G11+F12-E12 -> 301150 | H12: =IF(G12=0,"NIL",IF(G12>0,"CR","DR")) -> CR
A13: 45805 | B13: PAYMENT | C13: PAYMENT | D13: BOP ONLINE PAYMENT | E13: 31000 | G13: =G12+F13-E13 -> 270150 | H13: =IF(G13=0,"NIL",IF(G13>0,"CR","DR")) -> CR
A14: 45811 | B14: PAYMENT | C14: PAYMENT | D14: BOP ONLINE PAYMENT | E14: 30000 | G14: =G13+F14-E14 -> 240150 | H14: =IF(G14=0,"NIL",IF(G14>0,"CR","DR")) -> CR
A15: 45831 | B15: PURCHASE | C15: BILL#2671 | D15: PURCHASING FROM RWP | F15: 36500 | G15: =G14+F15-E15 -> 276650 | H15: =IF(G15=0,"NIL",IF(G15>0,"CR","DR")) -> CR
A16: 45832 | B16: PAYMENT | C16: PAYMENT | D16: BOP ONLINE PAYMENT | E16: 56650 | G16: =G15+F16-E16 -> 220000 | H16: =IF(G16=0,"NIL",IF(G16>0,"CR","DR")) -> CR
A17: 45838 | B17: PAYMENT | C17: PAYMENT | D17: BOP ONLINE PAYMENT | E17: 20000 | G17: =G16+F17-E17 -> 200000 | H17: =IF(G17=0,"NIL",IF(G17>0,"CR","DR")) -> CR
A18: 45839 | B18: PAYMENT | C18: PAYMENT | D18: PURCHASING FROM RWP | F18: 24500 | G18: =G17+F18-E18 -> 224500 | H18: =IF(G18=0,"NIL",IF(G18>0,"CR","DR")) -> CR
A19: 45846 | B19: PAYMENT | C19: PAYMENT | D19: BOP ONLINE PAYMENT | E19: 74500 | G19: =G18+F19-E19 -> 150000 | H19: =IF(G19=0,"NIL",IF(G19>0,"CR","DR")) -> CR
A20: 45846 | B20: PURCHASE | C20: Bill#2737 | D20: PURCHASING FROM RWP | F20: 11000 | G20: =G19+F20-E20 -> 161000 | H20: =IF(G20=0,"NIL",IF(G20>0,"CR","DR")) -> CR
A21: 45854 | B21: PAYMENT | C21: PAYMENT | D21: BOP ONLINE PAYMENT | E21: 20000 | G21: =G20+F21-E21 -> 141000 | H21: =IF(G21=0,"NIL",IF(G21>0,"CR","DR")) -> CR
A22: 45859 | B22: PURCHASE | C22: Bill#2701 | D22: PURCHASING FROM RWP | F22: 49000 | G22: =G21+F22-E22 -> 190000 | H22: =IF(G22=0,"NIL",IF(G22>0,"CR","DR")) -> CR
A23: 45859 | B23: PURCHASE | C23: PAYMENT | D23: BOP ONLINE PAYMENT | E23: 40000 | G23: =G22+F23-E23 -> 150000 | H23: =IF(G23=0,"NIL",IF(G23>0,"CR","DR")) -> CR
A24: 45861 | B24: PURCHASE | C24: BILL#2765 | D24: PURCHASING FROM RWP | F24: 217900 | G24: =G23+F24-E24 -> 367900 | H24: =IF(G24=0,"NIL",IF(G24>0,"CR","DR")) -> CR
A25: 45861 | B25: PURCHASE | C25: BILL2767 | D25: PURCHASING FROM RWP | F25: 34500 | G25: =G24+F25-E25 -> 402400 | H25: =IF(G25=0,"NIL",IF(G25>0,"CR","DR")) -> CR
A26: 45866 | B26: PAYMENT | C26: PAYMENT | D26: BOP ONLINE PAYMENT | E26: 52400 | G26: =G25+F26-E26 -> 350000 | H26: =IF(G26=0,"NIL",IF(G26>0,"CR","DR")) -> CR
A27: 45884 | B27: PAYMENT | C27: PAYMENT | D27: BOP ONLINE PAYMENT | E27: 50000 | G27: =G26+F27-E27 -> 300000 | H27: =IF(G27=0,"NIL",IF(G27>0,"CR","DR")) -> CR
A28: 45894 | B28: PAYMENT | C28: PAYMENT | D28: BOP ONLINE PAYMENT | E28: 30000 | G28: =G27+F28-E28 -> 270000 | H28: =IF(G28=0,"NIL",IF(G28>0,"CR","DR")) -> CR
A29: 45898 | B29: PAYMENT | C29: PAYMENT | D29: BOP ONLINE PAYMENT | E29: 40000 | G29: =G28+F29-E29 -> 230000 | H29: =IF(G29=0,"NIL",IF(G29>0,"CR","DR")) -> CR
A30: 45887 | B30: PURCHASE | C30: BILL2767 | D30: PURCHASING FROM RWP | F30: 26000 | G30: =G29+F30-E30 -> 256000 | H30: =IF(G30=0,"NIL",IF(G30>0,"CR","DR")) -> CR
A31: 45920 | B31: PAYMENT | C31: PAYMENT | D31: BOP ONLINE PAYMENT | E31: 106000 | G31: =G30+F31-E31 -> 150000 | H31: =IF(G31=0,"NIL",IF(G31>0,"CR","DR")) -> CR
A32: 45943 | B32: PURCHASE | C32: BILL#2919 | D32: PURCHASING FROM RWP | F32: 8000 | G32: =G31+F32-E32 -> 158000 | H32: =IF(G32=0,"NIL",IF(G32>0,"CR","DR")) -> CR
A33: 45943 | B33: PAYMENT | C33: PAYMENT | D33: BOP ONLINE PAYMENT | E33: 40000 | G33: =G32+F33-E33 -> 118000 | H33: =IF(G33=0,"NIL",IF(G33>0,"CR","DR")) -> CR
A34: 45949 | B34: PURCHASE | C34: BILL#3002 | D34: PURCHASING FROM RWP | F34: 116500 | G34: =G33+F34-E34 -> 234500 | H34: =IF(G34=0,"NIL",IF(G34>0,"CR","DR")) -> CR
A35: 45949 | B35: PURCHASE | C35: BILL#3003 | D35: PURCHASING FROM RWP | F35: 13400 | G35: =G34+F35-E35 -> 247900 | H35: =IF(G35=0,"NIL",IF(G35>0,"CR","DR")) -> CR
D36: TOTAL BALANCE | E36: =SUM(E6:E35) -> 785650 | F36: =SUM(F6:F35) -> 833550 | G36: =G5+F36-E36 -> 247900 | H36: =IF(G36=0,"NIL",IF(G36>0,"CR","DR")) -> CR

Sheet  ZAFAR & SONS RWP 4  
A1: TASNIM COMPUTERS SALES & SERVICE | J1: PAYABLE HOME
A2: ZAFAR & SONS RWP LEDGER
A3: FROM THE MONTH OF JANUARY 2024
A4: DATE | B4: TYPE | C4: REF# | D4: DESCRIPTION | E4: DEBIT | F4: CREDIT | G4: BALANCE
G5: ='ZAFAR & SONS RWP 3 '!G36 -> 247900
A6: 45952 | B6: PAYMENT | C6: PAYMENT | D6: BOP ONLINE PAYMENT | E6: 100000 | G6: =G5+F6-E6 -> 147900 | H6: =IF(G6=0,"NIL",IF(G6>0,"CR","DR")) -> CR
A7: 45955 | B7: RETURNE | C7: RETURNE | D7: I7 3RD K /8GB DDR 4 | E7: 12500 | G7: =G6+F7-E7 -> 135400 | H7: =IF(G7=0,"NIL",IF(G7>0,"CR","DR")) -> CR
A8: 45955 | B8: PAYMENT | C8: PAYMENT | D8: CASH PAYMENT | E8: 40000 | G8: =G7+F8-E8 -> 95400 | H8: =IF(G8=0,"NIL",IF(G8>0,"CR","DR")) -> CR
A9: 45958 | B9: PURCHASE | C9: BILL#3022 | D9: LED | F9: 57000 | G9: =G8+F9-E9 -> 152400 | H9: =IF(G9=0,"NIL",IF(G9>0,"CR","DR")) -> CR
A10: 45964 | B10: PURCHASE | C10: BILL#3022 | D10: HDD /RAM | F10: 44600 | G10: =G9+F10-E10 -> 197000 | H10: =IF(G10=0,"NIL",IF(G10>0,"CR","DR")) -> CR
A11: 45981 | B11: PAYMENT | C11: PAYMENT | D11: BOP ONLINE PAYMENT | E11: 50000 | G11: =G10+F11-E11 -> 147000 | H11: =IF(G11=0,"NIL",IF(G11>0,"CR","DR")) -> CR
A12: 45992 | B12: PAYMENT | C12: PAYMENT | D12: BOP ONLINE PAYMENT | E12: 50000 | G12: =G11+F12-E12 -> 97000 | H12: =IF(G12=0,"NIL",IF(G12>0,"CR","DR")) -> CR
A13: 45992 | B13: RETURNE | C13: RETURNE | D13: BILL BACK | E13: 4000 | G13: =G12+F13-E13 -> 93000 | H13: =IF(G13=0,"NIL",IF(G13>0,"CR","DR")) -> CR
A14: 45992 | B14: PURCHASE | C14: BILL#3023 | D14: PC PURCHASE | F14: 246050 | G14: =G13+F14-E14 -> 339050 | H14: =IF(G14=0,"NIL",IF(G14>0,"CR","DR")) -> CR
A15: 45993 | B15: PURCHASE | C15: BILL#3037 | D15: PC PURCHASE | F15: 40750 | G15: =G14+F15-E15 -> 379800 | H15: =IF(G15=0,"NIL",IF(G15>0,"CR","DR")) -> CR
A16: 46004 | B16: PAYMENT | C16: PAYMENT | D16: BOP ONLINE PAYMENT | E16: 50000 | G16: =G15+F16-E16 -> 329800 | H16: =IF(G16=0,"NIL",IF(G16>0,"CR","DR")) -> CR
A17: 46021 | B17: PAYMENT | C17: PAYMENT | D17: BOP ONLINE PAYMENT | E17: 30000 | G17: =G16+F17-E17 -> 299800 | H17: =IF(G17=0,"NIL",IF(G17>0,"CR","DR")) -> CR
A18: 45660 | B18: PURCHASE | C18: BILL#3023 | D18: PC PURCHASE | F18: 56900 | G18: =G17+F18-E18 -> 356700 | H18: =IF(G18=0,"NIL",IF(G18>0,"CR","DR")) -> CR
A19: 46036 | B19: PURCHASE | C19: BILL#3037 | D19: DELL 5050 BOX | F19: 12000 | G19: =G18+F19-E19 -> 368700 | H19: =IF(G19=0,"NIL",IF(G19>0,"CR","DR")) -> CR
A20: 46036 | B20: PAYMENT | C20: PAYMENT | D20: BOP ONLINE PAYMENT | E20: 50000 | G20: =G19+F20-E20 -> 318700 | H20: =IF(G20=0,"NIL",IF(G20>0,"CR","DR")) -> CR
A21: 45682 | B21: PURCHASE | D21: PROCESOR I5 3RD/DDR 3 4GB | F21: 5000 | G21: =G20+F21-E21 -> 323700 | H21: =IF(G21=0,"NIL",IF(G21>0,"CR","DR")) -> CR
A22: 46056 | B22: PAYMENT | C22: PAYMENT | D22: BOP ONLINE PAYMENT | E22: 55400 | G22: =G21+F22-E22 -> 268300 | H22: =IF(G22=0,"NIL",IF(G22>0,"CR","DR")) -> CR
A23: 46065 | B23: PURCHASE | C23: BILL3203 | D23: PC PURCHASE | F23: 116900 | G23: =G22+F23-E23 -> 385200 | H23: =IF(G23=0,"NIL",IF(G23>0,"CR","DR")) -> CR
A24: 46065 | B24: PURCHASE | C24: BILL3203 | D24: LED PURCHASE | F24: 111500 | G24: =G23+F24-E24 -> 496700 | H24: =IF(G24=0,"NIL",IF(G24>0,"CR","DR")) -> CR
A25: 46075 | B25: PAYMENT | C25: PAYMENT | D25: BOP ONLINE PAYMENT | E25: 50000 | G25: =G24+F25-E25 -> 446700 | H25: =IF(G25=0,"NIL",IF(G25>0,"CR","DR")) -> CR
A26: 46085 | B26: PAYMENT | C26: PAYMENT | D26: BOP ONLINE PAYMENT | E26: 30000 | G26: =G25+F26-E26 -> 416700 | H26: =IF(G26=0,"NIL",IF(G26>0,"CR","DR")) -> CR
A27: 46085 | B27: PAYMENT | C27: PAYMENT | D27: PC PURCHASE | F27: 79000 | G27: =G26+F27-E27 -> 495700 | H27: =IF(G27=0,"NIL",IF(G27>0,"CR","DR")) -> CR
A28: 46097 | B28: PAYMENT | C28: PAYMENT | D28: BOP ONLINE PAYMENT | E28: 95700 | G28: =G27+F28-E28 -> 400000 | H28: =IF(G28=0,"NIL",IF(G28>0,"CR","DR")) -> CR
A29: 46107 | B29: PAYMENT | C29: PAYMENT | D29: BOP ONLINE PAYMENT | E29: 50000 | G29: =G28+F29-E29 -> 350000 | H29: =IF(G29=0,"NIL",IF(G29>0,"CR","DR")) -> CR
A30: 46139 | B30: PURCHASE | C30: BILL#3296 | D30: PC PURCHASE | F30: 67800 | G30: =G29+F30-E30 -> 417800 | H30: =IF(G30=0,"NIL",IF(G30>0,"CR","DR")) -> CR
A31: 46161 | B31: PURCHASE | C31: BILL#3296 | D31: SSD PURCHASE | F31: 9000 | G31: =G30+F31-E31 -> 426800 | H31: =IF(G31=0,"NIL",IF(G31>0,"CR","DR")) -> CR
A32: 46161 | B32: PAYMENT | C32: PAYMENT | D32: BOP ONLINE PAYMENT | E32: 126800 | G32: =G31+F32-E32 -> 300000 | H32: =IF(G32=0,"NIL",IF(G32>0,"CR","DR")) -> CR
A33: 46179 | B33: PURCHASE | C33: BILL#3304 | D33: SSD PURCHASE | F33: 55600 | G33: =G32+F33-E33 -> 355600 | H33: =IF(G33=0,"NIL",IF(G33>0,"CR","DR")) -> CR
A34: 46189 | B34: PURCHASE | C34: BILL#3304 | D34: 24ich adjustment / dell mouse | F34: 17000 | G34: =G33+F34-E34 -> 372600 | H34: =IF(G34=0,"NIL",IF(G34>0,"CR","DR")) -> CR
A35: 46196 | B35: PAYMENT | C35: PAYMENT | D35: BOP ONLINE PAYMENT | E35: 35000 | G35: =G34+F35-E35 -> 337600 | H35: =IF(G35=0,"NIL",IF(G35>0,"CR","DR")) -> CR
D36: TOTAL BALANCE | E36: =SUM(E6:E35) -> 829400 | F36: =SUM(F6:F35) -> 919100 | G36: =G5+F36-E36 -> 337600 | H36: =IF(G36=0,"NIL",IF(G36>0,"CR","DR")) -> CR

Sheet  ZAFAR & SONS RWP 5 
A1: TASNIM COMPUTERS SALES & SERVICE | J1: PAYABLE HOME
A2: ZAFAR & SONS RWP LEDGER
A3: FROM THE MONTH OF JANUARY 2024
A4: DATE | B4: TYPE | C4: REF# | D4: DESCRIPTION | E4: DEBIT | F4: CREDIT | G4: BALANCE
G5: =' ZAFAR & SONS RWP 4 '!G36 -> 337600
A6: 46211 | B6: PAYMENT | C6: PAYMENT | D6: BOP ONLINE PAYMENT | E6: 50000 | G6: =G5+F6-E6 -> 287600 | H6: =IF(G6=0,"NIL",IF(G6>0,"CR","DR")) -> CR
A7: 46215 | B7: PURCHASE | C7: BILL#3451 | D7: DELL LED | F7: 103200 | G7: =G6+F7-E7 -> 390800 | H7: =IF(G7=0,"NIL",IF(G7>0,"CR","DR")) -> CR
A8: 46217 | B8: PAYMENT | C8: PAYMENT | D8: BOP ONLINE PAYMENT | E8: 140000 | G8: =G7+F8-E8 -> 250800 | H8: =IF(G8=0,"NIL",IF(G8>0,"CR","DR")) -> CR
A9: 46218 | B9: PURCHASE | C9: BILL#3468 | D9: graphic cards | F9: 32500 | G9: =G8+F9-E9 -> 283300 | H9: =IF(G9=0,"NIL",IF(G9>0,"CR","DR")) -> CR
A10: 46230 | B10: PAYMENT | C10: PAYMENT | D10: BOP ONLINE PAYMENT | E10: 40000 | G10: =G9+F10-E10 -> 243300 | H10: =IF(G10=0,"NIL",IF(G10>0,"CR","DR")) -> CR
A11: 46232 | B11: PURCHASE | C11: BILL#3502 | D11: DELL LED | F11: 147400 | G11: =G10+F11-E11 -> 390700 | H11: =IF(G11=0,"NIL",IF(G11>0,"CR","DR")) -> CR
A12: 46240 | B12: PAYMENT | C12: PAYMENT | D12: BOP ONLINE PAYMENT | E12: 50000 | G12: =G11+F12-E12 -> 340700 | H12: =IF(G12=0,"NIL",IF(G12>0,"CR","DR")) -> CR
A13: 46242 | B13: PURCHASE | C13: BILL#3515 | D13: LED /PC | F13: 29000 | G13: =G12+F13-E13 -> 369700 | H13: =IF(G13=0,"NIL",IF(G13>0,"CR","DR")) -> CR
A14: 46246 | B14: PAYMENT | C14: PAYMENT | D14: BOP ONLINE PAYMENT | E14: 30000 | G14: =G13+F14-E14 -> 339700 | H14: =IF(G14=0,"NIL",IF(G14>0,"CR","DR")) -> CR
A15: 46251 | B15: PURCHASE | C15: BILL#3539 | D15: graphic cards | F15: 22000 | G15: =G14+F15-E15 -> 361700 | H15: =IF(G15=0,"NIL",IF(G15>0,"CR","DR")) -> CR
G16: =G15+F16-E16 -> 361700 | H16: =IF(G16=0,"NIL",IF(G16>0,"CR","DR")) -> CR
G17: =G16+F17-E17 -> 361700 | H17: =IF(G17=0,"NIL",IF(G17>0,"CR","DR")) -> CR
G18: =G17+F18-E18 -> 361700 | H18: =IF(G18=0,"NIL",IF(G18>0,"CR","DR")) -> CR
G19: =G18+F19-E19 -> 361700 | H19: =IF(G19=0,"NIL",IF(G19>0,"CR","DR")) -> CR
G20: =G19+F20-E20 -> 361700 | H20: =IF(G20=0,"NIL",IF(G20>0,"CR","DR")) -> CR
G21: =G20+F21-E21 -> 361700 | H21: =IF(G21=0,"NIL",IF(G21>0,"CR","DR")) -> CR
G22: =G21+F22-E22 -> 361700 | H22: =IF(G22=0,"NIL",IF(G22>0,"CR","DR")) -> CR
G23: =G22+F23-E23 -> 361700 | H23: =IF(G23=0,"NIL",IF(G23>0,"CR","DR")) -> CR
G24: =G23+F24-E24 -> 361700 | H24: =IF(G24=0,"NIL",IF(G24>0,"CR","DR")) -> CR
G25: =G24+F25-E25 -> 361700 | H25: =IF(G25=0,"NIL",IF(G25>0,"CR","DR")) -> CR
G26: =G25+F26-E26 -> 361700 | H26: =IF(G26=0,"NIL",IF(G26>0,"CR","DR")) -> CR
G27: =G26+F27-E27 -> 361700 | H27: =IF(G27=0,"NIL",IF(G27>0,"CR","DR")) -> CR
... G35: =G34+F35-E35 -> 361700 | H35: =IF(G35=0,"NIL",IF(G35>0,"CR","DR")) -> CR
D36: TOTAL BALANCE | E36: =SUM(E6:E35) -> 310000 | F36: =SUM(F6:F35) -> 334100 | G36: =G5+F36-E36 -> 361700 | H36: =IF(G36=0,"NIL",IF(G36>0,"CR","DR")) -> CR

Sheet AL AZIZ-LHR-1
A1: TASNIM COMPUTERS SALES & SERVICE
A2: AL-AZIZ LAHORE LEDGER
A3: FROM THE MONTH OF JULY-2019
A4: DATE | B4: TYPE | C4: REF# | D4: DESCRIPTION | E4: DEBIT | F4: CREDIT | G4: BALANCE
A6: 43663 | B6: PURCHASE | C6: BILL# 158542 | D6: BATTERIES 2 | E6: 0 | F6: 5150 | G6: =G5+F6-E6 -> 5150 | H6: =IF(G6=0,"NIL",IF(G6>0,"CR","DR")) -> CR
A7: 43663 | B7: PURCHASE | C7: BILL# 158549 | D7: 14" LED SLIM (30PIN) | E7: 0 | F7: 5150 | G7: =G6+F7-E7 -> 10300 | H7: =IF(G7=0,"NIL",IF(G7>0,"CR","DR")) -> CR
A8: 43668 | B8: PAYMENT | C8: RECIEPT# 4880801 | D8: ONLINE PAYMENT THROUGH BANK | E8: 10300 | F8: 0 | G8: =G7+F8-E8 -> 0 | H8: =IF(G8=0,"NIL",IF(G8>0,"CR","DR")) -> NIL
A9: 43668 | B9: PURCHASE | C9: BILL# 159186 | D9: 15.6" LED | E9: 0 | F9: 5200 | G9: =G8+F9-E9 -> 5200 | H9: =IF(G9=0,"NIL",IF(G9>0,"CR","DR")) -> CR
A10: 43675 | B10: PAYMENT | C10: RECIEPT# 5258638 | D10: ONLINE PAYMENT THROUGH BANK | E10: 5200 | F10: 0 | G10: =G9+F10-E10 -> 0 | H10: =IF(G10=0,"NIL",IF(G10>0,"CR","DR")) -> NIL
A11: 43678 | B11: PURCHASE | C11: BILL# 160459 | D11: LAPTOP FAN QTY-2 | E11: 0 | F11: 1300 | G11: =G10+F11-E11 -> 1300 | H11: =IF(G11=0,"NIL",IF(G11>0,"CR","DR")) -> CR
A12: 43678 | B12: PURCHASE | C12: BILL# 160460 | D12: HP 6930P BATTERY QTY-1 | E12: 0 | F12: 1800 | G12: =G11+F12-E12 -> 3100 | H12: =IF(G12=0,"NIL",IF(G12>0,"CR","DR")) -> CR
A13: 43677 | B13: PURCHASE | C13: BILL# 160276 | D13: LAPTOP FAN QTY-2 | E13: 0 | F13: 1100 | G13: =G12+F13-E13 -> 4200 | H13: =IF(G13=0,"NIL",IF(G13>0,"CR","DR")) -> CR
A14: 43680 | B14: PURCHASE | C14: BILL# 160696 | D14: BATTERY HP 8460 | E14: 0 | F14: 1900 | G14: =G13+F14-E14 -> 6100 | H14: =IF(G14=0,"NIL",IF(G14>0,"CR","DR")) -> CR
A15: 43682 | B15: PURCHASE | C15: BILL# 160885 | D15: BATTERY DELL E3340 | E15: 0 | F15: 2600 | G15: =G14+F15-E15 -> 8700 | H15: =IF(G15=0,"NIL",IF(G15>0,"CR","DR")) -> CR
A16: 43685 | B16: PAYMENT | C16: RECIEPT# 8293214 | D16: ONLINE PAYMENT THROUGH BANK | E16: 8600 | F16: 0 | G16: =G15+F16-E16 -> 100 | H16: =IF(G16=0,"NIL",IF(G16>0,"CR","DR")) -> CR
A17: 43684 | B17: PURCHASE | C17: BILL# 161274 | D17: BATTERY DELL E3340 | E17: 0 | F17: 2600 | G17: =G16+F17-E17 -> 2700 | H17: =IF(G17=0,"NIL",IF(G17>0,"CR","DR")) -> CR
... A22: 43720 | B22: PURCHASE | C22: BILL# 165119 | D22: 15.6" LED HP PROBOOK | E22: 0 | F22: 5200 | G22: =G21+F22-E22 -> 5400 | H22: =IF(G22=0,"NIL",IF(G22>0,"CR","DR")) -> CR
A23: 43725 | B23: PAYMENT | C23: RECIEPT# 8295682 | D23: ONLINE PAYMENT THROUGH BANK | E23: 5300 | G23: =G22+F23-E23 -> 100 | H23: =IF(G23=0,"NIL",IF(G23>0,"CR","DR")) -> CR
A24: 43724 | B24: PURCHASE | C24: BILL# 165542 | D24: DELL 14" LED | E24: 0 | F24: 5400 | G24: =G23+F24-E24 -> 5500 | H24: =IF(G24=0,"NIL",IF(G24>0,"CR","DR")) -> CR
A25: 43725 | B25: PURCHASE | C25: BILL# 165744 | D25: HP BATTERY 440 | E25: 0 | F25: 1900 | G25: =G24+F25-E25 -> 7400 | H25: =IF(G25=0,"NIL",IF(G25>0,"CR","DR")) -> CR
A26: 43729 | B26: RETURN | C26: BILL# 165744 | D26: BETTERY HP 440 G3/RO04 RETURN | E26: 1900 | F26: 0 | G26: =G25+F26-E26 -> 5500 | H26: =IF(G26=0,"NIL",IF(G26>0,"CR","DR")) -> CR
A27: 43727 | B27: PURCHASE | C27: BILL# 166101 | D27: HP BATTERY 430 | E27: 0 | F27: 1900 | G27: =G26+F27-E27 -> 7400 | H27: =IF(G27=0,"NIL",IF(G27>0,"CR","DR")) -> CR
A28: 43729 | B28: PURCHASE | C28: BILL# 166310 | D28: 14" LED DELL | E28: 0 | F28: 5350 | G28: =G27+F28-E28 -> 12750 | H28: =IF(G28=0,"NIL",IF(G28>0,"CR","DR")) -> CR
A29: 43731 | B29: PAYMENT | C29: RECIEPT# 8295374 | D29: ONLINE PAYMENT THROUGH BANK | E29: 7300 | F29: 0 | G29: =G28+F29-E29 -> 5450 | H29: =IF(G29=0,"NIL",IF(G29>0,"CR","DR")) -> CR
A30: 43729 | B30: PURCHASE | C30: BILL# 166298 | D30: BATTERY HP | E30: 0 | F30: 1900 | G30: =G29+F30-E30 -> 7350 | H30: =IF(G30=0,"NIL",IF(G30>0,"CR","DR")) -> CR
A31: 43731 | B31: PURCHASE | C31: BILL# 166492 | D31: 15.6" LED DELL | E31: 0 | F31: 5400 | G31: =G30+F31-E31 -> 12750 | H31: =IF(G31=0,"NIL",IF(G31>0,"CR","DR")) -> CR
A32: 43738 | B32: PAYMENT | C32: RECIEPT# 8299915 | D32: ONLINE PAYMENT THROUGH BANK | E32: 12650 | F32: 0 | G32: =G31+F32-E32 -> 100 | H32: =IF(G32=0,"NIL",IF(G32>0,"CR","DR")) -> CR
A33: 43746 | B33: PURCHASE | C33: BILL# 168239 | D33: BATTERY DELL 4050 | E33: 0 | F33: 1900 | G33: =G32+F33-E33 -> 2000 | H33: =IF(G33=0,"NIL",IF(G33>0,"CR","DR")) -> CR
A34: 43750 | B34: PURCHASE | C34: BILL# 168458 | D34: KEYBOARD D4110 | E34: 0 | F34: 1000 | G34: =G33+F34-E34 -> 3000 | H34: =IF(G34=0,"NIL",IF(G34>0,"CR","DR")) -> CR
A35: 43752 | B35: PAYMENT | C35: RECIEPT# 8297390 | D35: ONLINE PAYMENT THROUGH BANK | E35: 2900 | F35: 0 | G35: =G34+F35-E35 -> 100 | H35: =IF(G35=0,"NIL",IF(G35>0,"CR","DR")) -> CR
D36: TOTAL BALANCE | E36: =SUM(E6:E35) -> 59950 | F36: =SUM(F6:F35) -> 60050 | G36: =G5+F36-E36 -> 100 | H36: =IF(G36=0,"NIL",IF(G36>0,"CR","DR")) -> CR

Sheet AL AZIZ-LHR-2
A1: TASNIM COMPUTERS SALES & SERVICE
A2: AL-AZIZ LAHORE LEDGER
A3: FROM THE MONTH OF JULY-2019
A4: DATE | B4: TYPE | C4: REF# | D4: DESCRIPTION | E4: DEBIT | F4: CREDIT | G4: BALANCE
D5: BALANCE B/F | G5: ='AL AZIZ-LHR-1'!G36 -> 100
A6: 43752 | B6: PURCHASE | C6: BILL# 169137 | D6: BATTERY LAPTOP | E6: 0 | F6: 1900 | G6: =G5+F6-E6 -> 2000 | H6: =IF(G6=0,"NIL",IF(G6>0,"CR","DR")) -> CR
A7: 43752 | B7: PURCHASE | C7: BILL# 169098 | D7: LED 15.6" SLIM | E7: 0 | F7: 5400 | G7: =G6+F7-E7 -> 7400 | H7: =IF(G7=0,"NIL",IF(G7>0,"CR","DR")) -> CR
A8: 43753 | B8: PURCHASE | C8: BILL# 169369 | D8: BATTERY LAPTOP | E8: 0 | F8: 1900 | G8: =G7+F8-E8 -> 9300 | H8: =IF(G8=0,"NIL",IF(G8>0,"CR","DR")) -> CR
A9: 43759 | B9: PAYMENT | C9: RECIEPT# 9469433 | D9: ONLINE PAYMENT THROUGH BANK | E9: 9200 | F9: 0 | G9: =G8+F9-E9 -> 100 | H9: =IF(G9=0,"NIL",IF(G9>0,"CR","DR")) -> CR
A10: 43759 | B10: PURCHASE | C10: BILL# 170120 | D10: 15.6" LED SLIM | E10: 0 | F10: 5400 | G10: =G9+F10-E10 -> 5500 | H10: =IF(G10=0,"NIL",IF(G10>0,"CR","DR")) -> CR
A11: 43760 | B11: PURCHASE | C11: BILL# 170341 | D11: BATTERY LAPTOP | E11: 0 | F11: 2200 | G11: =G10+F11-E11 -> 7700 | H11: =IF(G11=0,"NIL",IF(G11>0,"CR","DR")) -> CR
A12: 43765 | B12: RETURN | C12: RETURN BILL BAK | D12: BATTERY DELL LAPTOP BILL# 170341 | E12: 2100 | F12: 0 | G12: =G11+F12-E12 -> 5600 | H12: =IF(G12=0,"NIL",IF(G12>0,"CR","DR")) -> CR
A13: 43766 | B13: PAYMENT | C13: RECIEPT# 9468612 | D13: ONLINE PAYMENT THROUGH BANK | E13: 5400 | F13: 0 | G13: =G12+F13-E13 -> 200 | H13: =IF(G13=0,"NIL",IF(G13>0,"CR","DR")) -> CR
A14: 43771 | B14: PURCHASE | C14: BILL# 171423 | D14: DELL BATTRIES E6420 QTY-2 | E14: 0 | F14: 4400 | G14: =G13+F14-E14 -> 4600 | H14: =IF(G14=0,"NIL",IF(G14>0,"CR","DR")) -> CR
A15: 43774 | B15: PURCHASE | C15: BILL# 171700 | D15: BATTERY D3521 | E15: 0 | F15: 2250 | G15: =G14+F15-E15 -> 6850 | H15: =IF(G15=0,"NIL",IF(G15>0,"CR","DR")) -> CR
A16: 43787 | B16: PAYMENT | C16: RECIEPT# 5263075 | D16: ONLINE PAYMENT THROUGH BANK | E16: 6650 | F16: 0 | G16: =G15+F16-E16 -> 200 | H16: =IF(G16=0,"NIL",IF(G16>0,"CR","DR")) -> CR
A17: 43794 | B17: PURCHASE | C17: BILL# 173646 | D17: 14" LED SLIM | E17: 0 | F17: 6000 | G17: =G16+F17-E17 -> 6200 | H17: =IF(G17=0,"NIL",IF(G17>0,"CR","DR")) -> CR
... A35: 43939 | B35: PURCHASE | C35: BILL# 186379 | D35: 15.6" LED SLIM | E35: 0 | F35: 5750 | G35: =G34+F35-E35 -> 5750 | H35: =IF(G35=0,"NIL",IF(G35>0,"CR","DR")) -> CR
D36: TOTAL BALANCE | E36: =SUM(E6:E35) -> 55850 | F36: =SUM(F6:F35) -> 61500 | G36: =G5+F36-E36 -> 5750 | H36: =IF(G36=0,"NIL",IF(G36>0,"CR","DR")) -> CR

Sheet AL AZIZ-LHR-3
A1: TASNIM COMPUTERS SALES & SERVICE
A2: AL-AZIZ LAHORE LEDGER
A3: FROM THE MONTH OF JULY-2019
A4: DATE | B4: TYPE | C4: REF# | D4: DESCRIPTION | E4: DEBIT | F4: CREDIT | G4: BALANCE
D5: BALANCE B/F | G5: ='AL AZIZ-LHR-2'!G36 -> 5750
A6: 43944 | B6: PURCHASE | C6: BILL# 186427 | D6: HP BATTERY | E6: 0 | F6: 2250 | G6: =G5+F6-E6 -> 8000 | H6: =IF(G6=0,"NIL",IF(G6>0,"CR","DR")) -> CR
A7: 43949 | B7: PAYMENT | C7: RECIEPT#7671345 | D7: ONLINE PAYMENT THROUGH BANK | E7: 8000 | F7: 0 | G7: =G6+F7-E7 -> 0 | H7: =IF(G7=0,"NIL",IF(G7>0,"CR","DR")) -> NIL
A8: 43951 | B8: PURCHASE | C8: BILL# 186577 | D8: 15.6" LED & BATTERY HP | E8: 0 | F8: 7600 | G8: =G7+F8-E8 -> 7600 | H8: =IF(G8=0,"NIL",IF(G8>0,"CR","DR")) -> CR
A9: 43950 | B9: PURCHASE | C9: BILL# 186549 | D9: HP BATTERY | E9: 0 | F9: 2200 | G9: =G8+F9-E9 -> 9800 | H9: =IF(G9=0,"NIL",IF(G9>0,"CR","DR")) -> CR
A10: 43958 | B10: PURCHASE | C10: BILL# 186788 | D10: 14" LED SLIM | E10: 0 | F10: 5700 | G10: =G9+F10-E10 -> 15500 | H10: =IF(G10=0,"NIL",IF(G10>0,"CR","DR")) -> CR
A11: 43972 | B11: PURCHASE | C11: BILL# 187876 | D11: 15.6" LED SLIM | E11: 0 | F11: 5700 | G11: =G10+F11-E11 -> 21200 | H11: =IF(G11=0,"NIL",IF(G11>0,"CR","DR")) -> CR
A12: 43978 | B12: PURCHASE | C12: BILL# 188592 | D12: BATTERY AC 5742 | E12: 0 | F12: 2200 | G12: =G11+F12-E12 -> 23400 | H12: =IF(G12=0,"NIL",IF(G12>0,"CR","DR")) -> CR
A13: 43981 | B13: PURCHASE | C13: BILL# 188386 | D13: 14" LED SLIM & CABLE HP 8460 | E13: 0 | F13: 6600 | G13: =G12+F13-E13 -> 30000 | H13: =IF(G13=0,"NIL",IF(G13>0,"CR","DR")) -> CR
A14: 43984 | B14: PURCHASE | C14: BILL# 188808 | D14: DELL BATTERY 2 & HAIER KB | E14: 0 | F14: 8050 | G14: =G13+F14-E14 -> 38050 | H14: =IF(G14=0,"NIL",IF(G14>0,"CR","DR")) -> CR
A15: 43986 | B15: PAYMENT | C15: RECIEPT#8296579 | D15: ONLINE PAYMENT THROUGH BANK | E15: 38050 | F15: 0 | G15: =G14+F15-E15 -> 0 | H15: =IF(G15=0,"NIL",IF(G15>0,"CR","DR")) -> NIL
A16: 44012 | B16: PURCHASE | C16: BILL# 192752 | D16: BATTERY IBM G50-70 | E16: 0 | F16: 2100 | G16: =G15+F16-E16 -> 2100 | H16: =IF(G16=0,"NIL",IF(G16>0,"CR","DR")) -> CR
A17: 44013 | B17: PURCHASE | C17: BILL# 192821 | D17: BATTERY HP 8460 | E17: 0 | F17: 2200 | G17: =G16+F17-E17 -> 4300 | H17: =IF(G17=0,"NIL",IF(G17>0,"CR","DR")) -> CR
... A34: 44058 | B34: PAYMENT | C34: ID8477709510 | D34: ONLINE PAYMENT THROUGH EASY PAISA | E34: 18850 | F34: 0 | G34: =G33+F34-E34 -> 0 | H34: =IF(G34=0,"NIL",IF(G34>0,"CR","DR")) -> NIL
D35: BALANCE C/F | G35: =G34+F35-E35 -> 0 | H35: =IF(G35=0,"NIL",IF(G35>0,"CR","DR")) -> NIL
D36: TOTAL BALANCE | E36: =SUM(E6:E35) -> 101600 | F36: =SUM(F6:F35) -> 95850 | G36: =G5+F36-E36 -> 0 | H36: =IF(G36=0,"NIL",IF(G36>0,"CR","DR")) -> NIL

Sheet AL AZIZ-LHR-4
A1: TASNIM COMPUTERS SALES & SERVICE
A2: AL-AZIZ LAHORE LEDGER
A3: FROM THE MONTH OF JULY-2019
A4: DATE | B4: TYPE | C4: REF# | D4: DESCRIPTION | E4: DEBIT | F4: CREDIT | G4: BALANCE
D5: BALANCE B/F | G5: ='AL AZIZ-LHR-3'!G36 -> 0
